317 dimers loaded
multiprocessing.pool.RemoteTraceback: 
"""
Traceback (most recent call last):
  File "/nfs/turbo/umms-petefred/jaschwa/HDPRED/lib/python3.8/multiprocessing/pool.py", line 125, in worker
    result = (True, func(*args, **kwds))
  File "/nfs/turbo/umms-petefred/jaschwa/HDPRED/lib/python3.8/multiprocessing/pool.py", line 51, in starmapstar
    return list(itertools.starmap(args[0], args[1]))
  File "/nfs/turbo/umms-petefred/jaschwa/dimerDB/tools/../scripts/unredundant.py", line 61, in _distance_thread_helper
    return self.distance(self.things[i], self.things[j])
  File "/nfs/turbo/umms-petefred/jaschwa/dimerDB/tools/../scripts/unredundant.py", line 153, in distance
    dimer0_pdb0, dimer0_pdb1 = dimer2pdbs(dimer0_name, self.config['paths']['lib'])
  File "/nfs/turbo/umms-petefred/jaschwa/dimerDB/tools/../scripts/name_pdb.py", line 32, in dimer2pdbs
    pdb0, chain0, model0 = dimer_name.split('-')[0].split('_')
ValueError: not enough values to unpack (expected 3, got 2)
"""

The above exception was the direct cause of the following exception:

Traceback (most recent call last):
  File "manual_cluster.py", line 30, in <module>
    structures.initiate_distance_matrix(num_workers=int(args.cores))
  File "/nfs/turbo/umms-petefred/jaschwa/dimerDB/tools/../scripts/unredundant.py", line 73, in initiate_distance_matrix
    distances = p.starmap(self._distance_thread_helper, args)
  File "/nfs/turbo/umms-petefred/jaschwa/HDPRED/lib/python3.8/multiprocessing/pool.py", line 372, in starmap
    return self._map_async(func, iterable, starmapstar, chunksize).get()
  File "/nfs/turbo/umms-petefred/jaschwa/HDPRED/lib/python3.8/multiprocessing/pool.py", line 771, in get
    raise self._value
ValueError: not enough values to unpack (expected 3, got 2)
